<?xml version="1.0"?>
<robot name="C:/Users/fbiwa/Documents/Study and work software/inteligentne maszyny/controllers/BmwX5.urdf" xmlns:xacro="http://ros.org/wiki/xacro">
  <link name="base_link">
    <visual>
      <origin xyz="2.6775 0 0.29" rpy="1.570796 0 1.570796"/>
      <geometry>
        <box size="1.73 0.76 2"/>
      </geometry>
    </visual>
    <collision>
      <origin xyz="2.6775 0 0.29" rpy="1.570796 0 1.570796"/>
      <geometry>
        <box size="1.73 0.76 2"/>
      </geometry>
    </collision>
    <visual>
      <origin xyz="0.5875 0 0.63" rpy="1.570796 0 1.570796"/>
      <geometry>
        <box size="1.73 1.44 2.14"/>
      </geometry>
    </visual>
    <collision>
      <origin xyz="0.5875 0 0.63" rpy="1.570796 0 1.570796"/>
      <geometry>
        <box size="1.73 1.44 2.14"/>
      </geometry>
    </collision>
    <visual>
      <origin xyz="-0.1725 0 0.53" rpy="1.570796 0 1.570796"/>
      <geometry>
        <box size="1.73 0.78 1.41"/>
      </geometry>
    </visual>
    <collision>
      <origin xyz="-0.1725 0 0.53" rpy="1.570796 0 1.570796"/>
      <geometry>
        <box size="1.73 0.78 1.41"/>
      </geometry>
    </collision>
  </link>
  <joint name="rpm_needle_motor" type="revolute">
    <parent link="base_link"/>
    <child link="rpm needle"/>
    <axis xyz="0.055 0 -0.049"/>
    <limit effort="10" lower="0" upper="4.42" velocity="10"/>
    <origin xyz="2.16 0.3389 0.7319" rpy="0 0 0"/>
  </joint>
  <link name="rpm needle">
  </link>
  <joint name="speed_needle_motor" type="revolute">
    <parent link="base_link"/>
    <child link="speed needle"/>
    <axis xyz="0.055 0 -0.049"/>
    <limit effort="10" lower="0" upper="4.42" velocity="10"/>
    <origin xyz="0 0.1746 -0.0011" rpy="0 0 0"/>
  </joint>
  <link name="speed needle">
  </link>
  <joint name="steering_wheel_motor" type="continuous">
    <parent link="base_link"/>
    <child link="vehicle steering wheel"/>
    <axis xyz="0 -0.88 2.6"/>
    <limit effort="10" velocity="10"/>
    <origin xyz="-0.13 -0.0835 -0.1208" rpy="1.596589 -0.377786 1.436071"/>
  </joint>
  <link name="vehicle steering wheel">
  </link>
  <joint name="indicator_lever_motor" type="revolute">
    <parent link="base_link"/>
    <child link="solid"/>
    <axis xyz="0 0 1"/>
    <limit effort="10" lower="-0.4" upper="0.4" velocity="100"/>
    <origin xyz="0.533 0.58 2.09" rpy="1.570796 0 1.570796"/>
  </joint>
  <link name="solid">
  </link>
  <joint name="left_wiper_motor" type="revolute">
    <parent link="base_link"/>
    <child link="left wiper"/>
    <axis xyz="-1.25 -0.08 -1.85"/>
    <limit effort="10" lower="0" upper="1.6" velocity="10"/>
    <origin xyz="1.88 -1.46 0.307" rpy="0 0 0"/>
  </joint>
  <link name="left wiper">
  </link>
  <joint name="right_wiper_motor" type="revolute">
    <parent link="base_link"/>
    <child link="right wiper"/>
    <axis xyz="-1.7 0.04 -2.19"/>
    <limit effort="10" lower="0" upper="1.6" velocity="10"/>
    <origin xyz="0.09 -0.58 -0.05" rpy="0 0 0"/>
  </joint>
  <link name="right wiper">
  </link>
  <link name="interior_left_indicators">
  </link>
  <joint name="base_link_interior_left_indicators_joint" type="fixed">
    <parent link="base_link"/>
    <child link="interior_left_indicators"/>
    <origin xyz="-2.55 -0.05 -0.79" rpy="0 0 0"/>
  </joint>
  <link name="interior_right_indicators">
  </link>
  <joint name="base_link_interior_right_indicators_joint" type="fixed">
    <parent link="base_link"/>
    <child link="interior_right_indicators"/>
    <origin xyz="0 0 0" rpy="0 0 0"/>
  </joint>
  <link name="backwards_lights">
  </link>
  <joint name="base_link_backwards_lights_joint" type="fixed">
    <parent link="base_link"/>
    <child link="backwards_lights"/>
    <origin xyz="0 0 0" rpy="0 0 0"/>
  </joint>
  <link name="rear_lights">
  </link>
  <joint name="base_link_rear_lights_joint" type="fixed">
    <parent link="base_link"/>
    <child link="rear_lights"/>
    <origin xyz="0 0 0" rpy="0 0 0"/>
  </joint>
  <link name="brake_lights">
  </link>
  <joint name="base_link_brake_lights_joint" type="fixed">
    <parent link="base_link"/>
    <child link="brake_lights"/>
    <origin xyz="0 0 0" rpy="0 0 0"/>
  </joint>
  <link name="antifog_lights">
  </link>
  <joint name="base_link_antifog_lights_joint" type="fixed">
    <parent link="base_link"/>
    <child link="antifog_lights"/>
    <origin xyz="0 0 0" rpy="0 0 0"/>
  </joint>
  <link name="left_indicators">
  </link>
  <joint name="base_link_left_indicators_joint" type="fixed">
    <parent link="base_link"/>
    <child link="left_indicators"/>
    <origin xyz="0 0 0" rpy="0 0 0"/>
  </joint>
  <link name="right_indicators">
  </link>
  <joint name="base_link_right_indicators_joint" type="fixed">
    <parent link="base_link"/>
    <child link="right_indicators"/>
    <origin xyz="0 0 0" rpy="0 0 0"/>
  </joint>
  <link name="front_lights">
  </link>
  <joint name="base_link_front_lights_joint" type="fixed">
    <parent link="base_link"/>
    <child link="front_lights"/>
    <origin xyz="0 0 0" rpy="0 0 0"/>
  </joint>
  <link name="gps">
  </link>
  <joint name="base_link_gps_joint" type="fixed">
    <parent link="base_link"/>
    <child link="gps"/>
    <origin xyz="0 0 0" rpy="0 0 0"/>
  </joint>
  <link name="gyro">
  </link>
  <joint name="base_link_gyro_joint" type="fixed">
    <parent link="base_link"/>
    <child link="gyro"/>
    <origin xyz="0 0 0" rpy="0 0 0"/>
  </joint>
  <link name="camera_right_fender">
  </link>
  <joint name="base_link_camera_right_fender_joint" type="fixed">
    <parent link="base_link"/>
    <child link="camera_right_fender"/>
    <origin xyz="2.48 -0.946 0.51" rpy="-1.492687 0.280326 -4.172031"/>
  </joint>
  <link name="camera_left_fender">
  </link>
  <joint name="base_link_camera_left_fender_joint" type="fixed">
    <parent link="base_link"/>
    <child link="camera_left_fender"/>
    <origin xyz="2.48 0.946 0.51" rpy="-1.648884 0.280258 1.030452"/>
  </joint>
  <link name="camera_right_pillar">
  </link>
  <joint name="base_link_camera_right_pillar_joint" type="fixed">
    <parent link="base_link"/>
    <child link="camera_right_pillar"/>
    <origin xyz="1.079 -0.89 0.935" rpy="-1.450468 0.524924 -2.437031"/>
  </joint>
  <link name="camera_left_pillar">
  </link>
  <joint name="base_link_camera_left_pillar_joint" type="fixed">
    <parent link="base_link"/>
    <child link="camera_left_pillar"/>
    <origin xyz="1.079 0.89 0.935" rpy="-1.691093 0.524916 -0.704545"/>
  </joint>
  <link name="right common middle">
  </link>
  <joint name="base_link_right common middle_joint" type="fixed">
    <parent link="base_link"/>
    <child link="right common middle"/>
    <origin xyz="1.4 -2.5 -0.2855" rpy="0 0 0"/>
  </joint>
  <link name="left common middle">
  </link>
  <joint name="base_link_left common middle_joint" type="fixed">
    <parent link="base_link"/>
    <child link="left common middle"/>
    <origin xyz="1.4 2.5 -0.2855" rpy="0 0 0"/>
  </joint>
  <link name="middle right chess">
  </link>
  <joint name="base_link_middle right chess_joint" type="fixed">
    <parent link="base_link"/>
    <child link="middle right chess"/>
    <origin xyz="1.51 -2.52 -0.31" rpy="0 0 0"/>
  </joint>
  <link name="middle left chess">
  </link>
  <joint name="base_link_middle left chess_joint" type="fixed">
    <parent link="base_link"/>
    <child link="middle left chess"/>
    <origin xyz="1.51 2.52 -0.31" rpy="0 0 0"/>
  </joint>
  <link name="front common left">
  </link>
  <joint name="base_link_front common left_joint" type="fixed">
    <parent link="base_link"/>
    <child link="front common left"/>
    <origin xyz="4.92 1.9 -0.31" rpy="0 0 1.5708"/>
  </joint>
  <link name="front common right">
  </link>
  <joint name="base_link_front common right_joint" type="fixed">
    <parent link="base_link"/>
    <child link="front common right"/>
    <origin xyz="4.92 -1.9 -0.31" rpy="0 0 1.5708"/>
  </joint>
  <link name="front middle chess">
  </link>
  <joint name="base_link_front middle chess_joint" type="fixed">
    <parent link="base_link"/>
    <child link="front middle chess"/>
    <origin xyz="5.04 0 -0.3063" rpy="0 0 1.5708"/>
  </joint>
  <link name="rear common right">
  </link>
  <joint name="base_link_rear common right_joint" type="fixed">
    <parent link="base_link"/>
    <child link="rear common right"/>
    <origin xyz="-2.04 -1.7 -0.31" rpy="0 0 1.5708"/>
  </joint>
  <link name="rear common left">
  </link>
  <joint name="base_link_rear common left_joint" type="fixed">
    <parent link="base_link"/>
    <child link="rear common left"/>
    <origin xyz="-2.04 1.7 -0.31" rpy="0 0 1.5708"/>
  </joint>
  <link name="camera_helper">
  </link>
  <joint name="base_link_camera_helper_joint" type="fixed">
    <parent link="base_link"/>
    <child link="camera_helper"/>
    <origin xyz="-3.7 0 3.04625" rpy="-1.570796 1.57 -1.570796"/>
  </joint>
  <link name="rear middle chess">
  </link>
  <joint name="base_link_rear middle chess_joint" type="fixed">
    <parent link="base_link"/>
    <child link="rear middle chess"/>
    <origin xyz="-2.67 0 -0.2716" rpy="0 0 1.5708"/>
  </joint>
  <link name="distance sensor left front side">
  </link>
  <joint name="base_link_distance sensor left front side_joint" type="fixed">
    <parent link="base_link"/>
    <child link="distance sensor left front side"/>
    <origin xyz="3.515873 0.865199 0.039" rpy="0 0 1.57079"/>
  </joint>
  <link name="distance sensor front right">
  </link>
  <joint name="base_link_distance sensor front right_joint" type="fixed">
    <parent link="base_link"/>
    <child link="distance sensor front right"/>
    <origin xyz="3.588074 -0.81069 0.19" rpy="0 0 -0.7854"/>
  </joint>
  <link name="distance sensor right front side">
  </link>
  <joint name="base_link_distance sensor right front side_joint" type="fixed">
    <parent link="base_link"/>
    <child link="distance sensor right front side"/>
    <origin xyz="3.515873 -0.865199 0.039" rpy="0 0 -1.57079"/>
  </joint>
  <link name="distance sensor front left">
  </link>
  <joint name="base_link_distance sensor front left_joint" type="fixed">
    <parent link="base_link"/>
    <child link="distance sensor front left"/>
    <origin xyz="3.588074 0.81069 0.19" rpy="0 0 0.7854"/>
  </joint>
  <link name="distance sensor front lefter">
  </link>
  <joint name="base_link_distance sensor front lefter_joint" type="fixed">
    <parent link="base_link"/>
    <child link="distance sensor front lefter"/>
    <origin xyz="3.799743 0.375011 0.18" rpy="0 0 0.2618"/>
  </joint>
  <link name="distance sensor front righter">
  </link>
  <joint name="base_link_distance sensor front righter_joint" type="fixed">
    <parent link="base_link"/>
    <child link="distance sensor front righter"/>
    <origin xyz="3.799743 -0.375011 0.18" rpy="0 0 -0.2618"/>
  </joint>
  <link name="camera_front_bumper_wide">
  </link>
  <joint name="base_link_camera_front_bumper_wide_joint" type="fixed">
    <parent link="base_link"/>
    <child link="camera_front_bumper_wide"/>
    <origin xyz="3.86634 -0.000009 0.328299" rpy="-1.570796 0.523595 -1.570796"/>
  </joint>
  <link name="camera_front_top">
  </link>
  <joint name="base_link_camera_front_top_joint" type="fixed">
    <parent link="base_link"/>
    <child link="camera_front_top"/>
    <origin xyz="1.91408 0 1.255071" rpy="-1.570796 0.01953 -1.570796"/>
  </joint>
  <link name="distance sensor right side">
  </link>
  <joint name="base_link_distance sensor right side_joint" type="fixed">
    <parent link="base_link"/>
    <child link="distance sensor right side"/>
    <origin xyz="-0.505875 -0.9232 0.16" rpy="0 0 -1.570805"/>
  </joint>
  <link name="distance sensor left side">
  </link>
  <joint name="base_link_distance sensor left side_joint" type="fixed">
    <parent link="base_link"/>
    <child link="distance sensor left side"/>
    <origin xyz="-0.505871 0.923198 0.16" rpy="0 0 1.5708"/>
  </joint>
  <link name="distance sensor left">
  </link>
  <joint name="base_link_distance sensor left_joint" type="fixed">
    <parent link="base_link"/>
    <child link="distance sensor left"/>
    <origin xyz="-0.845978 0.798194 0.22" rpy="0 0 2.3562"/>
  </joint>
  <link name="distance sensor right">
  </link>
  <joint name="base_link_distance sensor right_joint" type="fixed">
    <parent link="base_link"/>
    <child link="distance sensor right"/>
    <origin xyz="-0.840982 -0.789534 0.18" rpy="0 0 -2.356205"/>
  </joint>
  <link name="distance sensor righter">
  </link>
  <joint name="base_link_distance sensor righter_joint" type="fixed">
    <parent link="base_link"/>
    <child link="distance sensor righter"/>
    <origin xyz="-0.930001 -0.32 0.18" rpy="0.000005 0 3.14159"/>
  </joint>
  <link name="distance sensor lefter">
  </link>
  <joint name="base_link_distance sensor lefter_joint" type="fixed">
    <parent link="base_link"/>
    <child link="distance sensor lefter"/>
    <origin xyz="-0.929999 0.32 0.18" rpy="0 0 3.14159"/>
  </joint>
  <link name="camera_rear">
  </link>
  <joint name="base_link_camera_rear_joint" type="fixed">
    <parent link="base_link"/>
    <child link="camera_rear"/>
    <origin xyz="-0.918811 0 0.731387" rpy="-1.570796 0.3927 1.570794"/>
  </joint>
  <link name="engine_speaker">
  </link>
  <joint name="base_link_engine_speaker_joint" type="fixed">
    <parent link="base_link"/>
    <child link="engine_speaker"/>
    <origin xyz="2.995 0 0" rpy="0 0 0"/>
  </joint>
  <joint name="right_rear_sensor" type="continuous">
    <parent link="base_link"/>
    <child link="rear right wheel"/>
    <axis xyz="0 1 0"/>
    <origin xyz="0 -0.814 0" rpy="3.141593 -1.363947 3.141593"/>
  </joint>
  <link name="rear right wheel">
    <visual>
      <origin xyz="0 0 0" rpy="1.570796 0 0"/>
      <geometry>
        <cylinder radius="0.374" length="0.25"/>
      </geometry>
    </visual>
    <collision>
      <origin xyz="0 0 0" rpy="1.570796 0 0"/>
      <geometry>
        <cylinder radius="0.374" length="0.25"/>
      </geometry>
    </collision>
  </link>
  <joint name="slot_rear right wheel_joint" type="fixed">
    <parent link="slot"/>
    <child link="rear right wheel"/>
    <origin xyz="0 0 0" rpy="0 0 0"/>
  </joint>
  <joint name="left_rear_sensor" type="continuous">
    <parent link="base_link"/>
    <child link="rear left wheel"/>
    <axis xyz="0 -1 0"/>
    <origin xyz="0 0.814 0" rpy="3.141593 0.084355 -0.000003"/>
  </joint>
  <link name="rear left wheel">
    <visual>
      <origin xyz="0 0 0" rpy="1.570796 0 0"/>
      <geometry>
        <cylinder radius="0.374" length="0.25"/>
      </geometry>
    </visual>
    <collision>
      <origin xyz="0 0 0" rpy="1.570796 0 0"/>
      <geometry>
        <cylinder radius="0.374" length="0.25"/>
      </geometry>
    </collision>
  </link>
  <joint name="slot_0_rear left wheel_joint" type="fixed">
    <parent link="slot_0"/>
    <child link="rear left wheel"/>
    <origin xyz="0 0 0" rpy="0 0 0"/>
  </joint>
</robot>
